{
  "summary": {
    "total_tests": 19,
    "passed": 8,
    "failed": 9,
    "errors": 2,
    "skipped": 0,
    "success_rate": 42.10526315789473,
    "total_duration": 47.621065616607666,
    "average_coverage": 0
  },
  "test_results": [
    {
      "name": "Integration Tests",
      "type": "integration",
      "status": "failed",
      "duration": 0.0922708511352539,
      "message": "Integration Tests failed with return code 1",
      "coverage": null,
      "performance_metrics": null,
      "error_details": "npm error Missing script: \"test:integration\"\nnpm error\nnpm error To see a list of scripts, run:\nnpm error   npm run\nnpm error A complete log of this run can be found in: /home/calelin/.npm/_logs/2025-10-20T07_54_00_727Z-debug-0.log\n"
    },
    {
      "name": "Performance Tests",
      "type": "performance",
      "status": "failed",
      "duration": 0.09575581550598145,
      "message": "Performance Tests failed with return code 1",
      "coverage": null,
      "performance_metrics": null,
      "error_details": "npm error Missing script: \"test:performance\"\nnpm error\nnpm error To see a list of scripts, run:\nnpm error   npm run\nnpm error A complete log of this run can be found in: /home/calelin/.npm/_logs/2025-10-20T07_54_00_813Z-debug-0.log\n"
    },
    {
      "name": "Java Unit Tests",
      "type": "unit",
      "status": "error",
      "duration": 0.0005552768707275391,
      "message": "Java Unit Tests failed with exception: [Errno 2] No such file or directory: 'mvn'",
      "coverage": null,
      "performance_metrics": null,
      "error_details": "[Errno 2] No such file or directory: 'mvn'"
    },
    {
      "name": "Java Integration Tests",
      "type": "integration",
      "status": "error",
      "duration": 0.0001678466796875,
      "message": "Java Integration Tests failed with exception: [Errno 2] No such file or directory: 'mvn'",
      "coverage": null,
      "performance_metrics": null,
      "error_details": "[Errno 2] No such file or directory: 'mvn'"
    },
    {
      "name": "Go Unit Tests",
      "type": "unit",
      "status": "failed",
      "duration": 0.0047397613525390625,
      "message": "Go Unit Tests failed with return code 1",
      "coverage": null,
      "performance_metrics": null,
      "error_details": "pattern ./operator/...: directory prefix operator does not contain main module or its selected dependencies\n"
    },
    {
      "name": "Go Integration Tests",
      "type": "integration",
      "status": "failed",
      "duration": 0.005189180374145508,
      "message": "Go Integration Tests failed with return code 1",
      "coverage": null,
      "performance_metrics": null,
      "error_details": "pattern ./operator/...: directory prefix operator does not contain main module or its selected dependencies\n"
    },
    {
      "name": "E2E Tests",
      "type": "e2e",
      "status": "failed",
      "duration": 2.0083398818969727,
      "message": "E2E Tests failed with return code 1",
      "coverage": null,
      "performance_metrics": null,
      "error_details": "\u001b[33mThe CJS build of Vite's Node API is deprecated. See https://vite.dev/guide/troubleshooting.html#vite-cjs-node-api-deprecated for more details.\u001b[39m\n\u23af\u23af\u23af\u23af\u23af\u23af\u23af Failed Tests 4 \u23af\u23af\u23af\u23af\u23af\u23af\u23af\n\n FAIL  test/e2e/pod.e2e.spec.ts > Pod E2E Tests > GET /k8s/Pod/list > should return list of all pods\n FAIL  test/e2e/pod.e2e.spec.ts > Pod E2E Tests > GET /k8s/Pod/list > should return 200 even with empty pod list\n FAIL  test/e2e/pod.e2e.spec.ts > Pod E2E Tests > GET /k8s/Pod/list/ns/:ns > should return pods from specific namespace\n FAIL  test/e2e/pod.e2e.spec.ts > Pod E2E Tests > GET /k8s/Pod/list/ns/:ns > should handle invalid namespace\n{\n  stack: 'AggregateError: \\n' +\n    '    at internalConnectMultiple (node:net:1122:18)\\n' +\n    '    at afterConnectMultiple (node:net:1689:7)',\n  errors: [\n    {\n      stack: 'Error: connect ECONNREFUSED ::1:3007\\n' +\n        '    at createConnectionError (node:net:1652:14)\\n' +\n        '    at afterConnectMultiple (node:net:1682:16)',\n      message: 'connect ECONNREFUSED ::1:3007',\n      errno: -111,\n      code: 'ECONNREFUSED',\n      syscall: 'connect',\n      address: '::1',\n      port: 3007,\n      constructor: 'Function<Error>',\n      name: 'Error',\n      toString: 'Function<toString>'\n    },\n    {\n      stack: 'Error: connect ECONNREFUSED 127.0.0.1:3007\\n' +\n        '    at createConnectionError (node:net:1652:14)\\n' +\n        '    at afterConnectMultiple (node:net:1682:16)',\n      message: 'connect ECONNREFUSED 127.0.0.1:3007',\n      errno: -111,\n      code: 'ECONNREFUSED',\n      syscall: 'connect',\n      address: '127.0.0.1',\n      port: 3007,\n      constructor: 'Function<Error>',\n      name: 'Error',\n      toString: 'Function<toString>'\n    }\n  ],\n  code: 'ECONNREFUSED',\n  response: undefined,\n  stackStr: 'AggregateError: \\n' +\n    '    at internalConnectMultiple (node:net:1122:18)\\n' +\n    '    at afterConnectMultiple (node:net:1689:7)',\n  nameStr: 'AggregateError',\n  expected: 'undefined',\n  actual: 'undefined',\n  message: '',\n  constructor: 'Function<AggregateError>',\n  name: 'AggregateError',\n  toString: 'Function<toString>',\n  stacks: [\n    {\n      method: 'internalConnectMultiple',\n      file: '/home/calelin/dev/k8s-playgrounds/node:net',\n      line: 1122,\n      column: 18\n    },\n    {\n      method: 'afterConnectMultiple',\n      file: '/home/calelin/dev/k8s-playgrounds/node:net',\n      line: 1689,\n      column: 7\n    }\n  ]\n}\n \u276f internalConnectMultiple node:net:1122:18\n \u276f afterConnectMultiple node:net:1689:7\n\n\u23af\u23af\u23af\u23af\u23af\u23af\u23af\u23af\u23af\u23af\u23af\u23af\u23af\u23af\u23af\u23af\u23af\u23af\u23af\u23af\u23af\u23af\u23af\u23af\u23af\u23af\u23af\u23af\u23af\u23af\nSerialized Error: { errors: [ { stack: 'Error: connect ECONNREFUSED ::1:3007\\n    at createConnectionError (node:net:1652:14)\\n    at afterConnectMultiple (node:net:1682:16)', message: 'connect ECONNREFUSED ::1:3007', errno: -111, code: 'ECONNREFUSED', syscall: 'connect', address: '::1', port: 3007, constructor: 'Function<Error>', name: 'Error', toString: 'Function<toString>' }, { stack: 'Error: connect ECONNREFUSED 127.0.0.1:3007\\n    at createConnectionError (node:net:1652:14)\\n    at afterConnectMultiple (node:net:1682:16)', message: 'connect ECONNREFUSED 127.0.0.1:3007', errno: -111, code: 'ECONNREFUSED', syscall: 'connect', address: '127.0.0.1', port: 3007, constructor: 'Function<Error>', name: 'Error', toString: 'Function<toString>' } ], code: 'ECONNREFUSED', response: undefined }\n\u23af\u23af\u23af\u23af\u23af\u23af\u23af\u23af\u23af\u23af\u23af\u23af\u23af\u23af\u23af\u23af\u23af\u23af\u23af\u23af\u23af\u23af\u23af\u23af[1/4]\u23af\n\n"
    },
    {
      "name": "Frontend Unit Tests",
      "type": "unit",
      "status": "failed",
      "duration": 2.645935535430908,
      "message": "Frontend Unit Tests failed with return code 1",
      "coverage": null,
      "performance_metrics": null,
      "error_details": "\u001b[33mThe CJS build of Vite's Node API is deprecated. See https://vite.dev/guide/troubleshooting.html#vite-cjs-node-api-deprecated for more details.\u001b[39m\n\u23af\u23af\u23af\u23af\u23af\u23af Failed Suites 1 \u23af\u23af\u23af\u23af\u23af\u23af\u23af\n\n FAIL  src/frontend/components/pod/PodListView.spec.ts [ src/frontend/components/pod/PodListView.spec.ts ]\nTypeError: Cannot set properties of undefined (setting 'stubs')\n \u276f test/setup-frontend.ts:5:19\n      3| \n      4| // Configure Vue Test Utils\n      5| config.globalThis.stubs = {\n       |                   ^\n      6|   'teleport': true,\n      7|   'n-config-provider': true,\n\n\u23af\u23af\u23af\u23af\u23af\u23af\u23af\u23af\u23af\u23af\u23af\u23af\u23af\u23af\u23af\u23af\u23af\u23af\u23af\u23af\u23af\u23af\u23af\u23af[1/1]\u23af\n\n"
    },
    {
      "name": "TinyURL System Tests",
      "type": "system",
      "status": "passed",
      "duration": 2.868563652038574,
      "message": "TinyURL System Tests completed successfully",
      "coverage": null,
      "performance_metrics": null,
      "error_details": null
    },
    {
      "name": "Newsfeed System Tests",
      "type": "system",
      "status": "passed",
      "duration": 4.0356667041778564,
      "message": "Newsfeed System Tests completed successfully",
      "coverage": null,
      "performance_metrics": null,
      "error_details": null
    },
    {
      "name": "Google Docs System Tests",
      "type": "system",
      "status": "passed",
      "duration": 4.03669548034668,
      "message": "Google Docs System Tests completed successfully",
      "coverage": null,
      "performance_metrics": null,
      "error_details": null
    },
    {
      "name": "Quora System Tests",
      "type": "system",
      "status": "passed",
      "duration": 3.8467659950256348,
      "message": "Quora System Tests completed successfully",
      "coverage": null,
      "performance_metrics": null,
      "error_details": null
    },
    {
      "name": "Monitoring System Tests",
      "type": "system",
      "status": "passed",
      "duration": 3.272303819656372,
      "message": "Monitoring System Tests completed successfully",
      "coverage": null,
      "performance_metrics": null,
      "error_details": null
    },
    {
      "name": "Load Balancer System Tests",
      "type": "system",
      "status": "failed",
      "duration": 5.88570237159729,
      "message": "Load Balancer System Tests failed with return code 1",
      "coverage": null,
      "performance_metrics": null,
      "error_details": "\u001b[33mThe CJS build of Vite's Node API is deprecated. See https://vite.dev/guide/troubleshooting.html#vite-cjs-node-api-deprecated for more details.\u001b[39m\n\n\u23af\u23af\u23af\u23af Unhandled Rejection \u23af\u23af\u23af\u23af\u23af\nError: Request failed\n \u276f systems/load-balancer-system/load-balancer.test.ts:505:62\n    503|         })\n    504| \n    505|         const mockRequestHandler = vi.fn().mockRejectedValue(new Error\u2026\n       |                                                              ^\n    506|         loadBalancer.handleRequest('client1', 'test-request', mockRequ\u2026\n    507|       })\n \u276f systems/load-balancer-system/load-balancer.test.ts:497:14\n \u276f node_modules/@vitest/runner/dist/index.js:135:14\n \u276f node_modules/@vitest/runner/dist/index.js:60:26\n \u276f runTest node_modules/@vitest/runner/dist/index.js:781:17\n \u276f runSuite node_modules/@vitest/runner/dist/index.js:909:15\n \u276f runSuite node_modules/@vitest/runner/dist/index.js:909:15\n \u276f runSuite node_modules/@vitest/runner/dist/index.js:909:15\n \u276f runFiles node_modules/@vitest/runner/dist/index.js:958:5\n\nThis error originated in \"systems/load-balancer-system/load-balancer.test.ts\" test file. It doesn't mean the error was thrown inside the file itself, but while it was running.\nThe latest test that might've caused the error is \"should emit circuit breaker opened event\". It might mean one of the following:\n- The error was thrown, while Vitest was running this test.\n- If the error occurred after the test had been completed, this was the last documented test before it was thrown.\n\n\u23af\u23af\u23af\u23af Unhandled Rejection \u23af\u23af\u23af\u23af\u23af\nError: Always fails\n \u276f systems/load-balancer-system/load-balancer.test.ts:525:62\n    523|         })\n    524| \n    525|         const mockRequestHandler = vi.fn().mockRejectedValue(new Error\u2026\n       |                                                              ^\n    526|         loadBalancer.handleRequest('client1', 'test-request', mockRequ\u2026\n    527|       })\n \u276f systems/load-balancer-system/load-balancer.test.ts:511:14\n \u276f node_modules/@vitest/runner/dist/index.js:135:14\n \u276f node_modules/@vitest/runner/dist/index.js:60:26\n \u276f runTest node_modules/@vitest/runner/dist/index.js:781:17\n \u276f runSuite node_modules/@vitest/runner/dist/index.js:909:15\n \u276f runSuite node_modules/@vitest/runner/dist/index.js:909:15\n \u276f runSuite node_modules/@vitest/runner/dist/index.js:909:15\n \u276f runFiles node_modules/@vitest/runner/dist/index.js:958:5\n\nThis error originated in \"systems/load-balancer-system/load-balancer.test.ts\" test file. It doesn't mean the error was thrown inside the file itself, but while it was running.\nThe latest test that might've caused the error is \"should handle server health changes\". It might mean one of the following:\n- The error was thrown, while Vitest was running this test.\n- If the error occurred after the test had been completed, this was the last documented test before it was thrown.\n\n"
    },
    {
      "name": "Backend Unit Tests",
      "type": "unit",
      "status": "failed",
      "duration": 11.9327712059021,
      "message": "Backend Unit Tests failed with return code 1",
      "coverage": null,
      "performance_metrics": null,
      "error_details": "\u001b[33mThe CJS build of Vite's Node API is deprecated. See https://vite.dev/guide/troubleshooting.html#vite-cjs-node-api-deprecated for more details.\u001b[39m\n\n\u23af\u23af\u23af\u23af Unhandled Rejection \u23af\u23af\u23af\u23af\u23af\nError: Delete failed\n \u276f src/backend/k8s/secret/secret.controller.spec.ts:421:32\n    419|       vi.spyOn(k8sService.secretService, 'Delete')\n    420|         .mockResolvedValueOnce(undefined)\n    421|         .mockRejectedValueOnce(new Error('Delete failed'))\n       |                                ^\n    422|         .mockResolvedValueOnce(undefined)\n    423| \n \u276f node_modules/@vitest/runner/dist/index.js:135:14\n \u276f node_modules/@vitest/runner/dist/index.js:60:26\n \u276f runTest node_modules/@vitest/runner/dist/index.js:781:17\n \u276f runSuite node_modules/@vitest/runner/dist/index.js:909:15\n \u276f runSuite node_modules/@vitest/runner/dist/index.js:909:15\n \u276f runSuite node_modules/@vitest/runner/dist/index.js:909:15\n \u276f runFiles node_modules/@vitest/runner/dist/index.js:958:5\n \u276f startTests node_modules/@vitest/runner/dist/index.js:967:3\n \u276f node_modules/vitest/dist/chunks/runtime-runBaseTests.oAvMKtQC.js:116:7\n\nThis error originated in \"src/backend/k8s/secret/secret.controller.spec.ts\" test file. It doesn't mean the error was thrown inside the file itself, but while it was running.\n\n\u23af\u23af\u23af\u23af Unhandled Rejection \u23af\u23af\u23af\u23af\u23af\nError: Delete failed\n \u276f src/backend/k8s/PersistentVolume/PersistentVolume.controller.spec.ts:451:32\n    449|       vi.spyOn(persistentVolumeService, 'Delete')\n    450|         .mockResolvedValueOnce(undefined)\n    451|         .mockRejectedValueOnce(new Error('Delete failed'))\n       |                                ^\n    452|         .mockResolvedValueOnce(undefined)\n    453| \n \u276f node_modules/@vitest/runner/dist/index.js:135:14\n \u276f node_modules/@vitest/runner/dist/index.js:60:26\n \u276f runTest node_modules/@vitest/runner/dist/index.js:781:17\n \u276f runSuite node_modules/@vitest/runner/dist/index.js:909:15\n \u276f runSuite node_modules/@vitest/runner/dist/index.js:909:15\n \u276f runSuite node_modules/@vitest/runner/dist/index.js:909:15\n \u276f runFiles node_modules/@vitest/runner/dist/index.js:958:5\n \u276f startTests node_modules/@vitest/runner/dist/index.js:967:3\n \u276f node_modules/vitest/dist/chunks/runtime-runBaseTests.oAvMKtQC.js:116:7\n\nThis error originated in \"src/backend/k8s/PersistentVolume/PersistentVolume.controller.spec.ts\" test file. It doesn't mean the error was thrown inside the file itself, but while it was running.\n\n\u23af\u23af\u23af\u23af Unhandled Rejection \u23af\u23af\u23af\u23af\u23af\nError: Delete failed\n \u276f src/backend/k8s/PersistentVolume/PersistentVolume.controller.spec.ts:499:21\n    497| \n    498|     it('should handle deletion errors', async () => {\n    499|       const error = new Error('Delete failed')\n       |                     ^\n    500|       vi.spyOn(persistentVolumeService, 'Delete').mockRejectedValue(er\u2026\n    501| \n \u276f node_modules/@vitest/runner/dist/index.js:135:14\n \u276f node_modules/@vitest/runner/dist/index.js:60:26\n \u276f runTest node_modules/@vitest/runner/dist/index.js:781:17\n \u276f runSuite node_modules/@vitest/runner/dist/index.js:909:15\n \u276f runSuite node_modules/@vitest/runner/dist/index.js:909:15\n \u276f runSuite node_modules/@vitest/runner/dist/index.js:909:15\n \u276f runFiles node_modules/@vitest/runner/dist/index.js:958:5\n \u276f startTests node_modules/@vitest/runner/dist/index.js:967:3\n \u276f node_modules/vitest/dist/chunks/runtime-runBaseTests.oAvMKtQC.js:116:7\n\nThis error originated in \"src/backend/k8s/PersistentVolume/PersistentVolume.controller.spec.ts\" test file. It doesn't mean the error was thrown inside the file itself, but while it was running.\n\n\u23af\u23af\u23af\u23af Unhandled Rejection \u23af\u23af\u23af\u23af\u23af\nError: Forbidden: User cannot delete PersistentVolume\n \u276f src/backend/k8s/PersistentVolume/PersistentVolume.controller.spec.ts:511:21\n    509| \n    510|     it('should handle permission errors during deletion', async () => {\n    511|       const error = new Error('Forbidden: User cannot delete Persisten\u2026\n       |                     ^\n    512|       vi.spyOn(persistentVolumeService, 'Delete').mockRejectedValue(er\u2026\n    513| \n \u276f node_modules/@vitest/runner/dist/index.js:135:14\n \u276f node_modules/@vitest/runner/dist/index.js:60:26\n \u276f runTest node_modules/@vitest/runner/dist/index.js:781:17\n \u276f runSuite node_modules/@vitest/runner/dist/index.js:909:15\n \u276f runSuite node_modules/@vitest/runner/dist/index.js:909:15\n \u276f runSuite node_modules/@vitest/runner/dist/index.js:909:15\n \u276f runFiles node_modules/@vitest/runner/dist/index.js:958:5\n \u276f startTests node_modules/@vitest/runner/dist/index.js:967:3\n \u276f node_modules/vitest/dist/chunks/runtime-runBaseTests.oAvMKtQC.js:116:7\n\nThis error originated in \"src/backend/k8s/PersistentVolume/PersistentVolume.controller.spec.ts\" test file. It doesn't mean the error was thrown inside the file itself, but while it was running.\n\n\u23af\u23af\u23af\u23af Unhandled Rejection \u23af\u23af\u23af\u23af\u23af\nError: Delete failed\n \u276f src/backend/k8s/configmap/configmap.controller.spec.ts:212:32\n    210|       vi.spyOn(k8sService.configMapService, 'Delete')\n    211|         .mockResolvedValueOnce(undefined)\n    212|         .mockRejectedValueOnce(new Error('Delete failed'))\n       |                                ^\n    213|         .mockResolvedValueOnce(undefined)\n    214| \n \u276f node_modules/@vitest/runner/dist/index.js:135:14\n \u276f node_modules/@vitest/runner/dist/index.js:60:26\n \u276f runTest node_modules/@vitest/runner/dist/index.js:781:17\n \u276f runSuite node_modules/@vitest/runner/dist/index.js:909:15\n \u276f runSuite node_modules/@vitest/runner/dist/index.js:909:15\n \u276f runSuite node_modules/@vitest/runner/dist/index.js:909:15\n \u276f runFiles node_modules/@vitest/runner/dist/index.js:958:5\n \u276f startTests node_modules/@vitest/runner/dist/index.js:967:3\n \u276f node_modules/vitest/dist/chunks/runtime-runBaseTests.oAvMKtQC.js:116:7\n\nThis error originated in \"src/backend/k8s/configmap/configmap.controller.spec.ts\" test file. It doesn't mean the error was thrown inside the file itself, but while it was running.\n\n\u23af\u23af\u23af\u23af Unhandled Rejection \u23af\u23af\u23af\u23af\u23af\nError: Delete failed\n \u276f src/backend/k8s/ingress/ingress.controller.spec.ts:312:32\n    310|       vi.spyOn(k8sService.ingressService, 'Delete')\n    311|         .mockResolvedValueOnce(undefined)\n    312|         .mockRejectedValueOnce(new Error('Delete failed'))\n       |                                ^\n    313|         .mockResolvedValueOnce(undefined)\n    314| \n \u276f node_modules/@vitest/runner/dist/index.js:135:14\n \u276f node_modules/@vitest/runner/dist/index.js:60:26\n \u276f runTest node_modules/@vitest/runner/dist/index.js:781:17\n \u276f runSuite node_modules/@vitest/runner/dist/index.js:909:15\n \u276f runSuite node_modules/@vitest/runner/dist/index.js:909:15\n \u276f runSuite node_modules/@vitest/runner/dist/index.js:909:15\n \u276f runFiles node_modules/@vitest/runner/dist/index.js:958:5\n \u276f startTests node_modules/@vitest/runner/dist/index.js:967:3\n \u276f node_modules/vitest/dist/chunks/runtime-runBaseTests.oAvMKtQC.js:116:7\n\nThis error originated in \"src/backend/k8s/ingress/ingress.controller.spec.ts\" test file. It doesn't mean the error was thrown inside the file itself, but while it was running.\n\n\u23af\u23af\u23af\u23af Unhandled Rejection \u23af\u23af\u23af\u23af\u23af\nError: Ingress not found\n \u276f src/backend/k8s/ingress/ingress.controller.spec.ts:369:32\n    367|       vi.spyOn(k8sService.ingressService, 'Delete')\n    368|         .mockResolvedValueOnce(undefined)\n    369|         .mockRejectedValueOnce(new Error('Ingress not found'))\n       |                                ^\n    370| \n    371|       const nsn = ['default/existing-ingress', 'default/nonexistent-in\u2026\n \u276f node_modules/@vitest/runner/dist/index.js:135:14\n \u276f node_modules/@vitest/runner/dist/index.js:60:26\n \u276f runTest node_modules/@vitest/runner/dist/index.js:781:17\n \u276f runSuite node_modules/@vitest/runner/dist/index.js:909:15\n \u276f runSuite node_modules/@vitest/runner/dist/index.js:909:15\n \u276f runSuite node_modules/@vitest/runner/dist/index.js:909:15\n \u276f runFiles node_modules/@vitest/runner/dist/index.js:958:5\n \u276f startTests node_modules/@vitest/runner/dist/index.js:967:3\n \u276f node_modules/vitest/dist/chunks/runtime-runBaseTests.oAvMKtQC.js:116:7\n\nThis error originated in \"src/backend/k8s/ingress/ingress.controller.spec.ts\" test file. It doesn't mean the error was thrown inside the file itself, but while it was running.\n\n\u23af\u23af\u23af\u23af Unhandled Rejection \u23af\u23af\u23af\u23af\u23af\nError: Delete failed\n \u276f src/backend/k8s/ns/ns.controller.spec.ts:274:32\n    272|       vi.spyOn(k8sService.nsService, 'Delete')\n    273|         .mockResolvedValueOnce(undefined)\n    274|         .mockRejectedValueOnce(new Error('Delete failed'))\n       |                                ^\n    275|         .mockResolvedValueOnce(undefined)\n    276| \n \u276f node_modules/@vitest/runner/dist/index.js:135:14\n \u276f node_modules/@vitest/runner/dist/index.js:60:26\n \u276f runTest node_modules/@vitest/runner/dist/index.js:781:17\n \u276f runSuite node_modules/@vitest/runner/dist/index.js:909:15\n \u276f runSuite node_modules/@vitest/runner/dist/index.js:909:15\n \u276f runSuite node_modules/@vitest/runner/dist/index.js:909:15\n \u276f runFiles node_modules/@vitest/runner/dist/index.js:958:5\n \u276f startTests node_modules/@vitest/runner/dist/index.js:967:3\n \u276f node_modules/vitest/dist/chunks/runtime-runBaseTests.oAvMKtQC.js:116:7\n\nThis error originated in \"src/backend/k8s/ns/ns.controller.spec.ts\" test file. It doesn't mean the error was thrown inside the file itself, but while it was running.\n\n\u23af\u23af\u23af\u23af Unhandled Rejection \u23af\u23af\u23af\u23af\u23af\nError: Forbidden: User cannot delete namespaces\n \u276f src/backend/k8s/ns/ns.controller.spec.ts:331:21\n    329| \n    330|     it('should handle permission errors during deletion', async () => {\n    331|       const error = new Error('Forbidden: User cannot delete namespace\u2026\n       |                     ^\n    332|       vi.spyOn(k8sService.nsService, 'Delete').mockRejectedValue(error)\n    333| \n \u276f node_modules/@vitest/runner/dist/index.js:135:14\n \u276f node_modules/@vitest/runner/dist/index.js:60:26\n \u276f runTest node_modules/@vitest/runner/dist/index.js:781:17\n \u276f runSuite node_modules/@vitest/runner/dist/index.js:909:15\n \u276f runSuite node_modules/@vitest/runner/dist/index.js:909:15\n \u276f runSuite node_modules/@vitest/runner/dist/index.js:909:15\n \u276f runFiles node_modules/@vitest/runner/dist/index.js:958:5\n \u276f startTests node_modules/@vitest/runner/dist/index.js:967:3\n \u276f node_modules/vitest/dist/chunks/runtime-runBaseTests.oAvMKtQC.js:116:7\n\nThis error originated in \"src/backend/k8s/ns/ns.controller.spec.ts\" test file. It doesn't mean the error was thrown inside the file itself, but while it was running.\n\n\u23af\u23af\u23af\u23af Unhandled Rejection \u23af\u23af\u23af\u23af\u23af\nError: Namespace is already being deleted\n \u276f src/backend/k8s/ns/ns.controller.spec.ts:343:21\n    341| \n    342|     it('should handle deletion of terminating namespace', async () => {\n    343|       const error = new Error('Namespace is already being deleted')\n       |                     ^\n    344|       vi.spyOn(k8sService.nsService, 'Delete').mockRejectedValue(error)\n    345| \n \u276f node_modules/@vitest/runner/dist/index.js:135:14\n \u276f node_modules/@vitest/runner/dist/index.js:60:26\n \u276f runTest node_modules/@vitest/runner/dist/index.js:781:17\n \u276f runSuite node_modules/@vitest/runner/dist/index.js:909:15\n \u276f runSuite node_modules/@vitest/runner/dist/index.js:909:15\n \u276f runSuite node_modules/@vitest/runner/dist/index.js:909:15\n \u276f runFiles node_modules/@vitest/runner/dist/index.js:958:5\n \u276f startTests node_modules/@vitest/runner/dist/index.js:967:3\n \u276f node_modules/vitest/dist/chunks/runtime-runBaseTests.oAvMKtQC.js:116:7\n\nThis error originated in \"src/backend/k8s/ns/ns.controller.spec.ts\" test file. It doesn't mean the error was thrown inside the file itself, but while it was running.\n\n\u23af\u23af\u23af\u23af Unhandled Rejection \u23af\u23af\u23af\u23af\u23af\nError: Delete failed\n \u276f src/backend/k8s/networkPolicy/NetworkPolicy.controller.spec.ts:274:32\n    272|       k8sService.networkPolicyService.Delete\n    273|         .mockResolvedValueOnce(undefined)\n    274|         .mockRejectedValueOnce(new Error('Delete failed'))\n       |                                ^\n    275|         .mockResolvedValueOnce(undefined)\n    276| \n \u276f node_modules/@vitest/runner/dist/index.js:135:14\n \u276f node_modules/@vitest/runner/dist/index.js:60:26\n \u276f runTest node_modules/@vitest/runner/dist/index.js:781:17\n \u276f runSuite node_modules/@vitest/runner/dist/index.js:909:15\n \u276f runSuite node_modules/@vitest/runner/dist/index.js:909:15\n \u276f runSuite node_modules/@vitest/runner/dist/index.js:909:15\n \u276f runFiles node_modules/@vitest/runner/dist/index.js:958:5\n \u276f startTests node_modules/@vitest/runner/dist/index.js:967:3\n \u276f node_modules/vitest/dist/chunks/runtime-runBaseTests.oAvMKtQC.js:116:7\n\nThis error originated in \"src/backend/k8s/networkPolicy/NetworkPolicy.controller.spec.ts\" test file. It doesn't mean the error was thrown inside the file itself, but while it was running.\n\n\u23af\u23af\u23af\u23af Unhandled Rejection \u23af\u23af\u23af\u23af\u23af\nError: Delete failed\n \u276f src/backend/k8s/ClusterRoleBinding/ClusterRoleBinding.controller.spec.ts:240:32\n    238|       vi.spyOn(k8sService.clusterRoleBindingService, 'Delete')\n    239|         .mockResolvedValueOnce(undefined)\n    240|         .mockRejectedValueOnce(new Error('Delete failed'))\n       |                                ^\n    241|         .mockResolvedValueOnce(undefined)\n    242| \n \u276f node_modules/@vitest/runner/dist/index.js:135:14\n \u276f node_modules/@vitest/runner/dist/index.js:60:26\n \u276f runTest node_modules/@vitest/runner/dist/index.js:781:17\n \u276f runSuite node_modules/@vitest/runner/dist/index.js:909:15\n \u276f runSuite node_modules/@vitest/runner/dist/index.js:909:15\n \u276f runSuite node_modules/@vitest/runner/dist/index.js:909:15\n \u276f runFiles node_modules/@vitest/runner/dist/index.js:958:5\n \u276f startTests node_modules/@vitest/runner/dist/index.js:967:3\n \u276f node_modules/vitest/dist/chunks/runtime-runBaseTests.oAvMKtQC.js:116:7\n\nThis error originated in \"src/backend/k8s/ClusterRoleBinding/ClusterRoleBinding.controller.spec.ts\" test file. It doesn't mean the error was thrown inside the file itself, but while it was running.\n\n\u23af\u23af\u23af\u23af Unhandled Rejection \u23af\u23af\u23af\u23af\u23af\nError: Forbidden: insufficient permissions\n \u276f src/backend/k8s/ClusterRoleBinding/ClusterRoleBinding.controller.spec.ts:289:21\n    287| \n    288|     it('should handle permission denied errors', async () => {\n    289|       const error = new Error('Forbidden: insufficient permissions')\n       |                     ^\n    290|       vi.spyOn(k8sService.clusterRoleBindingService, 'Delete').mockRej\u2026\n    291| \n \u276f node_modules/@vitest/runner/dist/index.js:135:14\n \u276f node_modules/@vitest/runner/dist/index.js:60:26\n \u276f runTest node_modules/@vitest/runner/dist/index.js:781:17\n \u276f runSuite node_modules/@vitest/runner/dist/index.js:909:15\n \u276f runSuite node_modules/@vitest/runner/dist/index.js:909:15\n \u276f runSuite node_modules/@vitest/runner/dist/index.js:909:15\n \u276f runFiles node_modules/@vitest/runner/dist/index.js:958:5\n \u276f startTests node_modules/@vitest/runner/dist/index.js:967:3\n \u276f node_modules/vitest/dist/chunks/runtime-runBaseTests.oAvMKtQC.js:116:7\n\nThis error originated in \"src/backend/k8s/ClusterRoleBinding/ClusterRoleBinding.controller.spec.ts\" test file. It doesn't mean the error was thrown inside the file itself, but while it was running.\n\n\u23af\u23af\u23af\u23af Unhandled Rejection \u23af\u23af\u23af\u23af\u23af\nError: Delete failed\n \u276f src/backend/k8s/storageClass/StorageClass.controller.spec.ts:323:32\n    321|       vi.spyOn(k8sService.storageClassService, 'Delete')\n    322|         .mockResolvedValueOnce(undefined)\n    323|         .mockRejectedValueOnce(new Error('Delete failed'))\n       |                                ^\n    324|         .mockResolvedValueOnce(undefined)\n    325| \n \u276f node_modules/@vitest/runner/dist/index.js:135:14\n \u276f node_modules/@vitest/runner/dist/index.js:60:26\n \u276f runTest node_modules/@vitest/runner/dist/index.js:781:17\n \u276f runSuite node_modules/@vitest/runner/dist/index.js:909:15\n \u276f runSuite node_modules/@vitest/runner/dist/index.js:909:15\n \u276f runSuite node_modules/@vitest/runner/dist/index.js:909:15\n \u276f runFiles node_modules/@vitest/runner/dist/index.js:958:5\n \u276f startTests node_modules/@vitest/runner/dist/index.js:967:3\n \u276f node_modules/vitest/dist/chunks/runtime-runBaseTests.oAvMKtQC.js:116:7\n\nThis error originated in \"src/backend/k8s/storageClass/StorageClass.controller.spec.ts\" test file. It doesn't mean the error was thrown inside the file itself, but while it was running.\n\n\u23af\u23af\u23af\u23af Unhandled Rejection \u23af\u23af\u23af\u23af\u23af\nError: Delete failed\n \u276f src/backend/k8s/horizontalpodautoscaler/HorizontalPodAutoscaler.controller.spec.ts:334:32\n    332|       vi.spyOn(k8sService.horizontalPodAutoscalerService, 'Delete')\n    333|         .mockResolvedValueOnce(undefined)\n    334|         .mockRejectedValueOnce(new Error('Delete failed'))\n       |                                ^\n    335|         .mockResolvedValueOnce(undefined)\n    336| \n \u276f node_modules/@vitest/runner/dist/index.js:135:14\n \u276f node_modules/@vitest/runner/dist/index.js:60:26\n \u276f runTest node_modules/@vitest/runner/dist/index.js:781:17\n \u276f runSuite node_modules/@vitest/runner/dist/index.js:909:15\n \u276f runSuite node_modules/@vitest/runner/dist/index.js:909:15\n \u276f runSuite node_modules/@vitest/runner/dist/index.js:909:15\n \u276f runFiles node_modules/@vitest/runner/dist/index.js:958:5\n \u276f startTests node_modules/@vitest/runner/dist/index.js:967:3\n \u276f node_modules/vitest/dist/chunks/runtime-runBaseTests.oAvMKtQC.js:116:7\n\nThis error originated in \"src/backend/k8s/horizontalpodautoscaler/HorizontalPodAutoscaler.controller.spec.ts\" test file. It doesn't mean the error was thrown inside the file itself, but while it was running.\n\n\u23af\u23af\u23af\u23af Unhandled Rejection \u23af\u23af\u23af\u23af\u23af\nError: Delete failed\n \u276f src/backend/k8s/RoleBinding/RoleBinding.controller.spec.ts:287:32\n    285|       vi.spyOn(k8sService.roleBindingService, 'Delete')\n    286|         .mockResolvedValueOnce(undefined)\n    287|         .mockRejectedValueOnce(new Error('Delete failed'))\n       |                                ^\n    288|         .mockResolvedValueOnce(undefined)\n    289| \n \u276f node_modules/@vitest/runner/dist/index.js:135:14\n \u276f node_modules/@vitest/runner/dist/index.js:60:26\n \u276f runTest node_modules/@vitest/runner/dist/index.js:781:17\n \u276f runSuite node_modules/@vitest/runner/dist/index.js:909:15\n \u276f runSuite node_modules/@vitest/runner/dist/index.js:909:15\n \u276f runSuite node_modules/@vitest/runner/dist/index.js:909:15\n \u276f runFiles node_modules/@vitest/runner/dist/index.js:958:5\n \u276f startTests node_modules/@vitest/runner/dist/index.js:967:3\n \u276f node_modules/vitest/dist/chunks/runtime-runBaseTests.oAvMKtQC.js:116:7\n\nThis error originated in \"src/backend/k8s/RoleBinding/RoleBinding.controller.spec.ts\" test file. It doesn't mean the error was thrown inside the file itself, but while it was running.\n\n\u23af\u23af\u23af\u23af Unhandled Rejection \u23af\u23af\u23af\u23af\u23af\nError: Delete failed\n \u276f src/backend/k8s/daemonset/daemonset.controller.spec.ts:179:32\n    177|       vi.spyOn(k8sService.daemonSetService, 'Delete')\n    178|         .mockResolvedValueOnce(undefined)\n    179|         .mockRejectedValueOnce(new Error('Delete failed'))\n       |                                ^\n    180|         .mockResolvedValueOnce(undefined)\n    181| \n \u276f node_modules/@vitest/runner/dist/index.js:135:14\n \u276f node_modules/@vitest/runner/dist/index.js:60:26\n \u276f runTest node_modules/@vitest/runner/dist/index.js:781:17\n \u276f runSuite node_modules/@vitest/runner/dist/index.js:909:15\n \u276f runSuite node_modules/@vitest/runner/dist/index.js:909:15\n \u276f runSuite node_modules/@vitest/runner/dist/index.js:909:15\n \u276f runFiles node_modules/@vitest/runner/dist/index.js:958:5\n \u276f startTests node_modules/@vitest/runner/dist/index.js:967:3\n \u276f node_modules/vitest/dist/chunks/runtime-runBaseTests.oAvMKtQC.js:116:7\n\nThis error originated in \"src/backend/k8s/daemonset/daemonset.controller.spec.ts\" test file. It doesn't mean the error was thrown inside the file itself, but while it was running.\n\n\u23af\u23af\u23af\u23af Unhandled Rejection \u23af\u23af\u23af\u23af\u23af\nError: Delete failed\n \u276f src/backend/k8s/ServiceAccount/ServiceAccount.controller.spec.ts:252:32\n    250|       vi.spyOn(k8sService.serviceAccountService, 'Delete')\n    251|         .mockResolvedValueOnce(undefined)\n    252|         .mockRejectedValueOnce(new Error('Delete failed'))\n       |                                ^\n    253|         .mockResolvedValueOnce(undefined)\n    254| \n \u276f node_modules/@vitest/runner/dist/index.js:135:14\n \u276f node_modules/@vitest/runner/dist/index.js:60:26\n \u276f runTest node_modules/@vitest/runner/dist/index.js:781:17\n \u276f runSuite node_modules/@vitest/runner/dist/index.js:909:15\n \u276f runSuite node_modules/@vitest/runner/dist/index.js:909:15\n \u276f runSuite node_modules/@vitest/runner/dist/index.js:909:15\n \u276f runFiles node_modules/@vitest/runner/dist/index.js:958:5\n \u276f startTests node_modules/@vitest/runner/dist/index.js:967:3\n \u276f node_modules/vitest/dist/chunks/runtime-runBaseTests.oAvMKtQC.js:116:7\n\nThis error originated in \"src/backend/k8s/ServiceAccount/ServiceAccount.controller.spec.ts\" test file. It doesn't mean the error was thrown inside the file itself, but while it was running.\n\n\u23af\u23af\u23af\u23af Unhandled Rejection \u23af\u23af\u23af\u23af\u23af\nError: Service account is in use\n \u276f src/backend/k8s/ServiceAccount/ServiceAccount.controller.spec.ts:292:28\n    290|     it('should handle deletion errors gracefully', async () => {\n    291|       vi.spyOn(k8sService.serviceAccountService, 'Delete')\n    292|         .mockRejectedValue(new Error('Service account is in use'))\n       |                            ^\n    293| \n    294|       const nsn = ['default/test-sa']\n \u276f node_modules/@vitest/runner/dist/index.js:135:14\n \u276f node_modules/@vitest/runner/dist/index.js:60:26\n \u276f runTest node_modules/@vitest/runner/dist/index.js:781:17\n \u276f runSuite node_modules/@vitest/runner/dist/index.js:909:15\n \u276f runSuite node_modules/@vitest/runner/dist/index.js:909:15\n \u276f runSuite node_modules/@vitest/runner/dist/index.js:909:15\n \u276f runFiles node_modules/@vitest/runner/dist/index.js:958:5\n \u276f startTests node_modules/@vitest/runner/dist/index.js:967:3\n \u276f node_modules/vitest/dist/chunks/runtime-runBaseTests.oAvMKtQC.js:116:7\n\nThis error originated in \"src/backend/k8s/ServiceAccount/ServiceAccount.controller.spec.ts\" test file. It doesn't mean the error was thrown inside the file itself, but while it was running.\n\n\u23af\u23af\u23af\u23af Unhandled Rejection \u23af\u23af\u23af\u23af\u23af\nError: Delete failed\n \u276f src/backend/k8s/replicaset/replicaset.controller.spec.ts:280:32\n    278|       vi.spyOn(k8sService.replicaSetService, 'Delete')\n    279|         .mockResolvedValueOnce(undefined)\n    280|         .mockRejectedValueOnce(new Error('Delete failed'))\n       |                                ^\n    281|         .mockResolvedValueOnce(undefined)\n    282| \n \u276f node_modules/@vitest/runner/dist/index.js:135:14\n \u276f node_modules/@vitest/runner/dist/index.js:60:26\n \u276f runTest node_modules/@vitest/runner/dist/index.js:781:17\n \u276f runSuite node_modules/@vitest/runner/dist/index.js:909:15\n \u276f runSuite node_modules/@vitest/runner/dist/index.js:909:15\n \u276f runSuite node_modules/@vitest/runner/dist/index.js:909:15\n \u276f runFiles node_modules/@vitest/runner/dist/index.js:958:5\n \u276f startTests node_modules/@vitest/runner/dist/index.js:967:3\n \u276f node_modules/vitest/dist/chunks/runtime-runBaseTests.oAvMKtQC.js:116:7\n\nThis error originated in \"src/backend/k8s/replicaset/replicaset.controller.spec.ts\" test file. It doesn't mean the error was thrown inside the file itself, but while it was running.\n\n\u23af\u23af\u23af\u23af Unhandled Rejection \u23af\u23af\u23af\u23af\u23af\nError: Not found\n \u276f src/backend/k8s/replicaset/replicaset.controller.spec.ts:348:32\n    346|       vi.spyOn(k8sService.replicaSetService, 'Delete')\n    347|         .mockResolvedValueOnce(undefined)\n    348|         .mockRejectedValueOnce(new Error('Not found'))\n       |                                ^\n    349|         .mockResolvedValueOnce(undefined)\n    350|         .mockRejectedValueOnce(new Error('Permission denied'))\n \u276f node_modules/@vitest/runner/dist/index.js:135:14\n \u276f node_modules/@vitest/runner/dist/index.js:60:26\n \u276f runTest node_modules/@vitest/runner/dist/index.js:781:17\n \u276f runSuite node_modules/@vitest/runner/dist/index.js:909:15\n \u276f runSuite node_modules/@vitest/runner/dist/index.js:909:15\n \u276f runSuite node_modules/@vitest/runner/dist/index.js:909:15\n \u276f runFiles node_modules/@vitest/runner/dist/index.js:958:5\n \u276f startTests node_modules/@vitest/runner/dist/index.js:967:3\n \u276f node_modules/vitest/dist/chunks/runtime-runBaseTests.oAvMKtQC.js:116:7\n\nThis error originated in \"src/backend/k8s/replicaset/replicaset.controller.spec.ts\" test file. It doesn't mean the error was thrown inside the file itself, but while it was running.\n\n\u23af\u23af\u23af\u23af Unhandled Rejection \u23af\u23af\u23af\u23af\u23af\nError: Permission denied\n \u276f src/backend/k8s/replicaset/replicaset.controller.spec.ts:350:32\n    348|         .mockRejectedValueOnce(new Error('Not found'))\n    349|         .mockResolvedValueOnce(undefined)\n    350|         .mockRejectedValueOnce(new Error('Permission denied'))\n       |                                ^\n    351|         .mockResolvedValueOnce(undefined)\n    352| \n \u276f node_modules/@vitest/runner/dist/index.js:135:14\n \u276f node_modules/@vitest/runner/dist/index.js:60:26\n \u276f runTest node_modules/@vitest/runner/dist/index.js:781:17\n \u276f runSuite node_modules/@vitest/runner/dist/index.js:909:15\n \u276f runSuite node_modules/@vitest/runner/dist/index.js:909:15\n \u276f runSuite node_modules/@vitest/runner/dist/index.js:909:15\n \u276f runFiles node_modules/@vitest/runner/dist/index.js:958:5\n \u276f startTests node_modules/@vitest/runner/dist/index.js:967:3\n \u276f node_modules/vitest/dist/chunks/runtime-runBaseTests.oAvMKtQC.js:116:7\n\nThis error originated in \"src/backend/k8s/replicaset/replicaset.controller.spec.ts\" test file. It doesn't mean the error was thrown inside the file itself, but while it was running.\n\n\u23af\u23af\u23af\u23af Unhandled Rejection \u23af\u23af\u23af\u23af\u23af\nError: Delete failed\n \u276f src/backend/k8s/PersistentVolumeClaim/PersistentVolumeClaim.controller.spec.ts:303:32\n    301|       vi.spyOn(k8sService.persistentVolumeClaimService, 'Delete')\n    302|         .mockResolvedValueOnce(undefined)\n    303|         .mockRejectedValueOnce(new Error('Delete failed'))\n       |                                ^\n    304|         .mockResolvedValueOnce(undefined)\n    305| \n \u276f node_modules/@vitest/runner/dist/index.js:135:14\n \u276f node_modules/@vitest/runner/dist/index.js:60:26\n \u276f runTest node_modules/@vitest/runner/dist/index.js:781:17\n \u276f runSuite node_modules/@vitest/runner/dist/index.js:909:15\n \u276f runSuite node_modules/@vitest/runner/dist/index.js:909:15\n \u276f runSuite node_modules/@vitest/runner/dist/index.js:909:15\n \u276f runFiles node_modules/@vitest/runner/dist/index.js:958:5\n \u276f startTests node_modules/@vitest/runner/dist/index.js:967:3\n \u276f node_modules/vitest/dist/chunks/runtime-runBaseTests.oAvMKtQC.js:116:7\n\nThis error originated in \"src/backend/k8s/PersistentVolumeClaim/PersistentVolumeClaim.controller.spec.ts\" test file. It doesn't mean the error was thrown inside the file itself, but while it was running.\n\n\u23af\u23af\u23af\u23af Unhandled Rejection \u23af\u23af\u23af\u23af\u23af\nError: PVC in use\n \u276f src/backend/k8s/PersistentVolumeClaim/PersistentVolumeClaim.controller.spec.ts:350:32\n    348|     it('should handle deletion errors gracefully', async () => {\n    349|       vi.spyOn(k8sService.persistentVolumeClaimService, 'Delete')\n    350|         .mockRejectedValueOnce(new Error('PVC in use'))\n       |                                ^\n    351|         .mockResolvedValueOnce(undefined)\n    352| \n \u276f node_modules/@vitest/runner/dist/index.js:135:14\n \u276f node_modules/@vitest/runner/dist/index.js:60:26\n \u276f runTest node_modules/@vitest/runner/dist/index.js:781:17\n \u276f runSuite node_modules/@vitest/runner/dist/index.js:909:15\n \u276f runSuite node_modules/@vitest/runner/dist/index.js:909:15\n \u276f runSuite node_modules/@vitest/runner/dist/index.js:909:15\n \u276f runFiles node_modules/@vitest/runner/dist/index.js:958:5\n \u276f startTests node_modules/@vitest/runner/dist/index.js:967:3\n \u276f node_modules/vitest/dist/chunks/runtime-runBaseTests.oAvMKtQC.js:116:7\n\nThis error originated in \"src/backend/k8s/PersistentVolumeClaim/PersistentVolumeClaim.controller.spec.ts\" test file. It doesn't mean the error was thrown inside the file itself, but while it was running.\n\n\u23af\u23af\u23af\u23af Unhandled Rejection \u23af\u23af\u23af\u23af\u23af\nError: Delete failed\n \u276f src/backend/k8s/statefulset/statefulset.controller.spec.ts:185:32\n    183|       vi.spyOn(k8sService.statefulSetService, 'Delete')\n    184|         .mockResolvedValueOnce(undefined)\n    185|         .mockRejectedValueOnce(new Error('Delete failed'))\n       |                                ^\n    186|         .mockResolvedValueOnce(undefined)\n    187| \n \u276f node_modules/@vitest/runner/dist/index.js:135:14\n \u276f node_modules/@vitest/runner/dist/index.js:60:26\n \u276f runTest node_modules/@vitest/runner/dist/index.js:781:17\n \u276f runSuite node_modules/@vitest/runner/dist/index.js:909:15\n \u276f runSuite node_modules/@vitest/runner/dist/index.js:909:15\n \u276f runSuite node_modules/@vitest/runner/dist/index.js:909:15\n \u276f runFiles node_modules/@vitest/runner/dist/index.js:958:5\n \u276f startTests node_modules/@vitest/runner/dist/index.js:967:3\n \u276f node_modules/vitest/dist/chunks/runtime-runBaseTests.oAvMKtQC.js:116:7\n\nThis error originated in \"src/backend/k8s/statefulset/statefulset.controller.spec.ts\" test file. It doesn't mean the error was thrown inside the file itself, but while it was running.\n\n\u23af\u23af\u23af\u23af Unhandled Rejection \u23af\u23af\u23af\u23af\u23af\nError: Delete failed\n \u276f src/backend/k8s/cronjob/cronjob.controller.spec.ts:159:32\n    157|       vi.spyOn(k8sService.cronJobService, 'Delete')\n    158|         .mockResolvedValueOnce(undefined)\n    159|         .mockRejectedValueOnce(new Error('Delete failed'))\n       |                                ^\n    160|         .mockResolvedValueOnce(undefined)\n    161| \n \u276f node_modules/@vitest/runner/dist/index.js:135:14\n \u276f node_modules/@vitest/runner/dist/index.js:60:26\n \u276f runTest node_modules/@vitest/runner/dist/index.js:781:17\n \u276f runSuite node_modules/@vitest/runner/dist/index.js:909:15\n \u276f runSuite node_modules/@vitest/runner/dist/index.js:909:15\n \u276f runSuite node_modules/@vitest/runner/dist/index.js:909:15\n \u276f runFiles node_modules/@vitest/runner/dist/index.js:958:5\n \u276f startTests node_modules/@vitest/runner/dist/index.js:967:3\n \u276f node_modules/vitest/dist/chunks/runtime-runBaseTests.oAvMKtQC.js:116:7\n\nThis error originated in \"src/backend/k8s/cronjob/cronjob.controller.spec.ts\" test file. It doesn't mean the error was thrown inside the file itself, but while it was running.\n\n\u23af\u23af\u23af\u23af Unhandled Rejection \u23af\u23af\u23af\u23af\u23af\nError: Delete failed\n \u276f src/backend/k8s/ClusterRole/ClusterRole.controller.spec.ts:239:32\n    237|       vi.spyOn(k8sService.clusterRoleService, 'Delete')\n    238|         .mockResolvedValueOnce(undefined)\n    239|         .mockRejectedValueOnce(new Error('Delete failed'))\n       |                                ^\n    240|         .mockResolvedValueOnce(undefined)\n    241| \n \u276f node_modules/@vitest/runner/dist/index.js:135:14\n \u276f node_modules/@vitest/runner/dist/index.js:60:26\n \u276f runTest node_modules/@vitest/runner/dist/index.js:781:17\n \u276f runSuite node_modules/@vitest/runner/dist/index.js:909:15\n \u276f runSuite node_modules/@vitest/runner/dist/index.js:909:15\n \u276f runSuite node_modules/@vitest/runner/dist/index.js:909:15\n \u276f runFiles node_modules/@vitest/runner/dist/index.js:958:5\n \u276f startTests node_modules/@vitest/runner/dist/index.js:967:3\n \u276f node_modules/vitest/dist/chunks/runtime-runBaseTests.oAvMKtQC.js:116:7\n\nThis error originated in \"src/backend/k8s/ClusterRole/ClusterRole.controller.spec.ts\" test file. It doesn't mean the error was thrown inside the file itself, but while it was running.\n\n\u23af\u23af\u23af\u23af Unhandled Rejection \u23af\u23af\u23af\u23af\u23af\nError: Cannot delete system cluster role\n \u276f src/backend/k8s/ClusterRole/ClusterRole.controller.spec.ts:287:21\n    285| \n    286|     it('should handle protected cluster role deletion error', async ()\u2026\n    287|       const error = new Error('Cannot delete system cluster role')\n       |                     ^\n    288|       vi.spyOn(k8sService.clusterRoleService, 'Delete').mockRejectedVa\u2026\n    289| \n \u276f node_modules/@vitest/runner/dist/index.js:135:14\n \u276f node_modules/@vitest/runner/dist/index.js:60:26\n \u276f runTest node_modules/@vitest/runner/dist/index.js:781:17\n \u276f runSuite node_modules/@vitest/runner/dist/index.js:909:15\n \u276f runSuite node_modules/@vitest/runner/dist/index.js:909:15\n \u276f runSuite node_modules/@vitest/runner/dist/index.js:909:15\n \u276f runFiles node_modules/@vitest/runner/dist/index.js:958:5\n \u276f startTests node_modules/@vitest/runner/dist/index.js:967:3\n \u276f node_modules/vitest/dist/chunks/runtime-runBaseTests.oAvMKtQC.js:116:7\n\nThis error originated in \"src/backend/k8s/ClusterRole/ClusterRole.controller.spec.ts\" test file. It doesn't mean the error was thrown inside the file itself, but while it was running.\n\n\u23af\u23af\u23af\u23af Unhandled Rejection \u23af\u23af\u23af\u23af\u23af\nError: Forbidden: User cannot delete cluster roles\n \u276f src/backend/k8s/ClusterRole/ClusterRole.controller.spec.ts:299:21\n    297| \n    298|     it('should handle permission errors during deletion', async () => {\n    299|       const error = new Error('Forbidden: User cannot delete cluster r\u2026\n       |                     ^\n    300|       vi.spyOn(k8sService.clusterRoleService, 'Delete').mockRejectedVa\u2026\n    301| \n \u276f node_modules/@vitest/runner/dist/index.js:135:14\n \u276f node_modules/@vitest/runner/dist/index.js:60:26\n \u276f runTest node_modules/@vitest/runner/dist/index.js:781:17\n \u276f runSuite node_modules/@vitest/runner/dist/index.js:909:15\n \u276f runSuite node_modules/@vitest/runner/dist/index.js:909:15\n \u276f runSuite node_modules/@vitest/runner/dist/index.js:909:15\n \u276f runFiles node_modules/@vitest/runner/dist/index.js:958:5\n \u276f startTests node_modules/@vitest/runner/dist/index.js:967:3\n \u276f node_modules/vitest/dist/chunks/runtime-runBaseTests.oAvMKtQC.js:116:7\n\nThis error originated in \"src/backend/k8s/ClusterRole/ClusterRole.controller.spec.ts\" test file. It doesn't mean the error was thrown inside the file itself, but while it was running.\n\n\u23af\u23af\u23af\u23af Unhandled Rejection \u23af\u23af\u23af\u23af\u23af\nError: Delete failed\n \u276f src/backend/k8s/Role/Role.controller.spec.ts:272:32\n    270|       vi.spyOn(k8sService.roleService, 'Delete')\n    271|         .mockResolvedValueOnce(undefined)\n    272|         .mockRejectedValueOnce(new Error('Delete failed'))\n       |                                ^\n    273|         .mockResolvedValueOnce(undefined)\n    274| \n \u276f node_modules/@vitest/runner/dist/index.js:135:14\n \u276f node_modules/@vitest/runner/dist/index.js:60:26\n \u276f runTest node_modules/@vitest/runner/dist/index.js:781:17\n \u276f runSuite node_modules/@vitest/runner/dist/index.js:909:15\n \u276f runSuite node_modules/@vitest/runner/dist/index.js:909:15\n \u276f runSuite node_modules/@vitest/runner/dist/index.js:909:15\n \u276f runFiles node_modules/@vitest/runner/dist/index.js:958:5\n \u276f startTests node_modules/@vitest/runner/dist/index.js:967:3\n \u276f node_modules/vitest/dist/chunks/runtime-runBaseTests.oAvMKtQC.js:116:7\n\nThis error originated in \"src/backend/k8s/Role/Role.controller.spec.ts\" test file. It doesn't mean the error was thrown inside the file itself, but while it was running.\n\n\u23af\u23af\u23af\u23af Unhandled Rejection \u23af\u23af\u23af\u23af\u23af\nError: Forbidden: User cannot delete roles\n \u276f src/backend/k8s/Role/Role.controller.spec.ts:329:21\n    327| \n    328|     it('should handle permission errors during deletion', async () => {\n    329|       const error = new Error('Forbidden: User cannot delete roles')\n       |                     ^\n    330|       vi.spyOn(k8sService.roleService, 'Delete').mockRejectedValue(err\u2026\n    331| \n \u276f node_modules/@vitest/runner/dist/index.js:135:14\n \u276f node_modules/@vitest/runner/dist/index.js:60:26\n \u276f runTest node_modules/@vitest/runner/dist/index.js:781:17\n \u276f runSuite node_modules/@vitest/runner/dist/index.js:909:15\n \u276f runSuite node_modules/@vitest/runner/dist/index.js:909:15\n \u276f runSuite node_modules/@vitest/runner/dist/index.js:909:15\n \u276f runFiles node_modules/@vitest/runner/dist/index.js:958:5\n \u276f startTests node_modules/@vitest/runner/dist/index.js:967:3\n \u276f node_modules/vitest/dist/chunks/runtime-runBaseTests.oAvMKtQC.js:116:7\n\nThis error originated in \"src/backend/k8s/Role/Role.controller.spec.ts\" test file. It doesn't mean the error was thrown inside the file itself, but while it was running.\n\n\u23af\u23af\u23af\u23af Unhandled Rejection \u23af\u23af\u23af\u23af\u23af\nError: Role not found\n \u276f src/backend/k8s/Role/Role.controller.spec.ts:341:21\n    339| \n    340|     it('should handle deletion of non-existent role', async () => {\n    341|       const error = new Error('Role not found')\n       |                     ^\n    342|       vi.spyOn(k8sService.roleService, 'Delete').mockRejectedValue(err\u2026\n    343| \n \u276f node_modules/@vitest/runner/dist/index.js:135:14\n \u276f node_modules/@vitest/runner/dist/index.js:60:26\n \u276f runTest node_modules/@vitest/runner/dist/index.js:781:17\n \u276f runSuite node_modules/@vitest/runner/dist/index.js:909:15\n \u276f runSuite node_modules/@vitest/runner/dist/index.js:909:15\n \u276f runSuite node_modules/@vitest/runner/dist/index.js:909:15\n \u276f runFiles node_modules/@vitest/runner/dist/index.js:958:5\n \u276f startTests node_modules/@vitest/runner/dist/index.js:967:3\n \u276f node_modules/vitest/dist/chunks/runtime-runBaseTests.oAvMKtQC.js:116:7\n\nThis error originated in \"src/backend/k8s/Role/Role.controller.spec.ts\" test file. It doesn't mean the error was thrown inside the file itself, but while it was running.\n\n\u23af\u23af\u23af\u23af Unhandled Rejection \u23af\u23af\u23af\u23af\u23af\nError: Delete failed\n \u276f src/backend/k8s/service/NetworkSvc.controller.spec.ts:161:32\n    159|       vi.spyOn(networkSvcService, 'Delete')\n    160|         .mockResolvedValueOnce(undefined)\n    161|         .mockRejectedValueOnce(new Error('Delete failed'))\n       |                                ^\n    162|         .mockResolvedValueOnce(undefined)\n    163| \n \u276f node_modules/@vitest/runner/dist/index.js:135:14\n \u276f node_modules/@vitest/runner/dist/index.js:60:26\n \u276f runTest node_modules/@vitest/runner/dist/index.js:781:17\n \u276f runSuite node_modules/@vitest/runner/dist/index.js:909:15\n \u276f runSuite node_modules/@vitest/runner/dist/index.js:909:15\n \u276f runSuite node_modules/@vitest/runner/dist/index.js:909:15\n \u276f runFiles node_modules/@vitest/runner/dist/index.js:958:5\n \u276f startTests node_modules/@vitest/runner/dist/index.js:967:3\n \u276f node_modules/vitest/dist/chunks/runtime-runBaseTests.oAvMKtQC.js:116:7\n\nThis error originated in \"src/backend/k8s/service/NetworkSvc.controller.spec.ts\" test file. It doesn't mean the error was thrown inside the file itself, but while it was running.\n\n\u23af\u23af\u23af\u23af Unhandled Rejection \u23af\u23af\u23af\u23af\u23af\nError: Delete failed\n \u276f src/backend/k8s/job/job.controller.spec.ts:209:32\n    207|       vi.spyOn(k8sService.jobService, 'Delete')\n    208|         .mockResolvedValueOnce(undefined)\n    209|         .mockRejectedValueOnce(new Error('Delete failed'))\n       |                                ^\n    210|         .mockResolvedValueOnce(undefined)\n    211| \n \u276f node_modules/@vitest/runner/dist/index.js:135:14\n \u276f node_modules/@vitest/runner/dist/index.js:60:26\n \u276f runTest node_modules/@vitest/runner/dist/index.js:781:17\n \u276f runSuite node_modules/@vitest/runner/dist/index.js:909:15\n \u276f runSuite node_modules/@vitest/runner/dist/index.js:909:15\n \u276f runSuite node_modules/@vitest/runner/dist/index.js:909:15\n \u276f runFiles node_modules/@vitest/runner/dist/index.js:958:5\n \u276f startTests node_modules/@vitest/runner/dist/index.js:967:3\n \u276f node_modules/vitest/dist/chunks/runtime-runBaseTests.oAvMKtQC.js:116:7\n\nThis error originated in \"src/backend/k8s/job/job.controller.spec.ts\" test file. It doesn't mean the error was thrown inside the file itself, but while it was running.\n\n"
    },
    {
      "name": "Messaging System Tests",
      "type": "system",
      "status": "passed",
      "duration": 2.0050113201141357,
      "message": "Messaging System Tests completed successfully",
      "coverage": null,
      "performance_metrics": null,
      "error_details": null
    },
    {
      "name": "Typeahead System Tests",
      "type": "system",
      "status": "failed",
      "duration": 7.872389554977417,
      "message": "Typeahead System Tests failed with return code 1",
      "coverage": null,
      "performance_metrics": null,
      "error_details": "\u001b[33mThe CJS build of Vite's Node API is deprecated. See https://vite.dev/guide/troubleshooting.html#vite-cjs-node-api-deprecated for more details.\u001b[39m\n\u23af\u23af\u23af\u23af\u23af\u23af\u23af Failed Tests 2 \u23af\u23af\u23af\u23af\u23af\u23af\u23af\n\n FAIL  systems/typeahead-system/typeahead.test.ts > TypeaheadSystem > Search Functionality > should perform case-sensitive search when enabled\nAssertionError: expected 7 to be 1 // Object.is equality\n\n- Expected\n+ Received\n\n- 1\n+ 7\n\n \u276f systems/typeahead-system/typeahead.test.ts:183:36\n    181|       const result2 = cleanTypeahead.search('apple')\n    182| \n    183|       expect(result1.items.length).toBe(1)\n       |                                    ^\n    184|       expect(result2.items.length).toBe(1)\n    185|       expect(result1.items[0].text).toBe('APPLE')\n\n\u23af\u23af\u23af\u23af\u23af\u23af\u23af\u23af\u23af\u23af\u23af\u23af\u23af\u23af\u23af\u23af\u23af\u23af\u23af\u23af\u23af\u23af\u23af\u23af[1/2]\u23af\n\n FAIL  systems/typeahead-system/typeahead.test.ts > TypeaheadSystem > Async Search > should debounce multiple rapid searches\nError: Test timed out in 5000ms.\nIf this is a long-running test, pass a timeout value as the last argument or configure it globally with \"testTimeout\".\n\u23af\u23af\u23af\u23af\u23af\u23af\u23af\u23af\u23af\u23af\u23af\u23af\u23af\u23af\u23af\u23af\u23af\u23af\u23af\u23af\u23af\u23af\u23af\u23af[2/2]\u23af\n\n"
    },
    {
      "name": "DNS System Tests",
      "type": "system",
      "status": "passed",
      "duration": 3.7725653648376465,
      "message": "DNS System Tests completed successfully",
      "coverage": null,
      "performance_metrics": null,
      "error_details": null
    },
    {
      "name": "Web Crawler System Tests",
      "type": "system",
      "status": "passed",
      "duration": 35.68841862678528,
      "message": "Web Crawler System Tests completed successfully",
      "coverage": null,
      "performance_metrics": null,
      "error_details": null
    }
  ],
  "performance_analysis": {
    "overall_performance": "good",
    "bottlenecks": [],
    "recommendations": []
  },
  "coverage_analysis": {
    "status": "no_coverage_data",
    "recommendations": [
      "Enable coverage reporting"
    ]
  },
  "recommendations": [
    "Fix 2 test errors"
  ],
  "timestamp": "2025-10-20T00:54:48.298547"
}
